<?xml version="1.0" ?>
<!-- =================================================================================== -->
<!-- |    This document was autogenerated by xacro from romo_left_arm.xacro            | -->
<!-- |    EDITING THIS FILE BY HAND IS NOT RECOMMENDED                                 | -->
<!-- =================================================================================== -->
<!-- ROMO_Manipulator Chain -->
<robot name="romo_left_arm" xmlns:xacro="http://www.ros.org/wiki/xacro">
  <material name="black">
    <color rgba="0.0 0.0 0.0 1.0"/>
  </material>
  <material name="white">
    <color rgba="1.0 1.0 1.0 1.0"/>
  </material>
  <material name="red">
    <color rgba="0.8 0.0 0.0 1.0"/>
  </material>
  <material name="blue">
    <color rgba="0.0 0.0 0.8 1.0"/>
  </material>
  <material name="green">
    <color rgba="0.0 0.8 0.0 1.0"/>
  </material>
  <material name="grey">
    <color rgba="0.5 0.5 0.5 1.0"/>
  </material>
  <material name="orange">
    <color rgba="1.0 0.423529411765 0.0392156862745 1.0"/>
  </material>
  <material name="brown">
    <color rgba="0.870588235294 0.811764705882 0.764705882353 1.0"/>
  </material>
  <!-- World -->
  <link name="left_base">
  </link>
  <!-- World fixed joint-->
  <joint name="left_fixed" type="fixed">
    <origin rpy="0 0 0" xyz="0 0 0"/>
    <parent link="left_base"/>
    <child link="link1"/>
  </joint>
  <!-- Link 1 -->
  <link name="link1">
    <collision>
      <origin rpy="0 0 0" xyz="0.0 0.0 0.0"/>
      <geometry>
        <mesh filename="package://romo_ros/meshes/left_chain_link1.stl"/>
      </geometry>
    </collision>
    <visual>
      <origin rpy="0 0 0" xyz="0.0 0.0 0.0"/>
      <geometry>
        <mesh filename="package://romo_ros/meshes/left_chain_link1.stl"/>
      </geometry>
      <material name="grey"/>
    </visual>
    <inertial>
      <origin xyz="0 0 0.0"/>
      <mass value="1"/>
      <inertia ixx="0.001" ixy="0.0" ixz="0.0" iyy="0.001" iyz="0.0" izz="0.001"/>
    </inertial>
  </link>
  <!-- Joint 1 -->
  <joint name="joint1" type="revolute">
    <parent link="link1"/>
    <child link="link2"/>
    <origin rpy="0 0 0" xyz="0.0 0.048 -0.026"/>
    <axis xyz="0 0 1"/>
    <limit effort="1000" lower="-2.8274333886" upper="2.8274333886" velocity="6.5"/>
  </joint>
  <!-- Transmission 1 -->
  <transmission name="tran1">
    <type>transmission_interface/SimpleTransmission</type>
    <joint name="joint1">
      <hardwareInterface>PositionJointInterface</hardwareInterface>
    </joint>
    <actuator name="motor1">
      <hardwareInterface>PositionJointInterface</hardwareInterface>
      <mechanicalReduction>1</mechanicalReduction>
    </actuator>
  </transmission>
  <!--  Link 2 -->
  <link name="link2">
    <collision>
      <origin rpy="0 0 0" xyz="0.0 -0.048 0.026"/>
      <geometry>
        <mesh filename="package://romo_ros/meshes/left_chain_link2.stl"/>
      </geometry>
    </collision>
    <visual>
      <origin rpy="0 0 0" xyz="0.0 -0.048 0.026"/>
      <geometry>
        <mesh filename="package://romo_ros/meshes/left_chain_link2.stl"/>
      </geometry>
      <material name="grey"/>
    </visual>
    <inertial>
      <origin xyz="0 -0.048 0.026"/>
      <mass value="0.5"/>
      <inertia ixx="0.001" ixy="0.0" ixz="0.0" iyy="0.001" iyz="0.0" izz="0.001"/>
    </inertial>
  </link>
  <!--  Joint 2 -->
  <joint name="joint2" type="revolute">
    <parent link="link2"/>
    <child link="link3"/>
    <origin rpy="0 0 0" xyz="0.0 -0.032 -0.027"/>
    <axis xyz="1 0 0"/>
    <limit effort="1000" lower="-2.8274333886" upper="2.8274333886" velocity="6.5"/>
  </joint>
  <!-- Transmission 2 -->
  <transmission name="tran2">
    <type>transmission_interface/SimpleTransmission</type>
    <joint name="joint2">
      <hardwareInterface>PositionJointInterface</hardwareInterface>
    </joint>
    <actuator name="motor2">
      <hardwareInterface>PositionJointInterface</hardwareInterface>
      <mechanicalReduction>1</mechanicalReduction>
    </actuator>
  </transmission>
  <!--  Link 3 -->
  <link name="link3">
    <collision>
      <origin rpy="0 0 0" xyz="0.0 -0.016 0.053"/>
      <geometry>
        <mesh filename="package://romo_ros/meshes/left_chain_link3.stl"/>
      </geometry>
    </collision>
    <visual>
      <origin rpy="0 0 0" xyz="0.0 -0.016 0.053"/>
      <geometry>
        <mesh filename="package://romo_ros/meshes/left_chain_link3.stl"/>
      </geometry>
      <material name="grey"/>
    </visual>
    <inertial>
      <origin xyz="0 -0.016 0.053"/>
      <mass value="0.5"/>
      <inertia ixx="0.001" ixy="0.0" ixz="0.0" iyy="0.001" iyz="0.0" izz="0.001"/>
    </inertial>
  </link>
  <!--  Joint 3 -->
  <joint name="joint3" type="revolute">
    <parent link="link3"/>
    <child link="link4"/>
    <origin rpy="0 0 0" xyz="0.0 -0.034 0.0"/>
    <axis xyz="0 -1 0"/>
    <limit effort="1000" lower="-2.8274333886" upper="2.8274333886" velocity="6.5"/>
  </joint>
  <!-- Transmission 3 -->
  <transmission name="tran3">
    <type>transmission_interface/SimpleTransmission</type>
    <joint name="joint3">
      <hardwareInterface>PositionJointInterface</hardwareInterface>
    </joint>
    <actuator name="motor3">
      <hardwareInterface>PositionJointInterface</hardwareInterface>
      <mechanicalReduction>1</mechanicalReduction>
    </actuator>
  </transmission>
  <!--  Link 4 -->
  <link name="link4">
    <collision>
      <origin rpy="0 0 0" xyz="0.0 0.018 0.053"/>
      <geometry>
        <mesh filename="package://romo_ros/meshes/left_chain_link4.stl"/>
      </geometry>
    </collision>
    <visual>
      <origin rpy="0 0 0" xyz="0.0 0.018 0.053"/>
      <geometry>
        <mesh filename="package://romo_ros/meshes/left_chain_link4.stl"/>
      </geometry>
      <material name="grey"/>
    </visual>
    <inertial>
      <origin xyz="0.0 0.018 0.053"/>
      <mass value="0.4"/>
      <inertia ixx="0.001" ixy="0.0" ixz="0.0" iyy="0.001" iyz="0.0" izz="0.001"/>
    </inertial>
  </link>
  <!--  Joint 4 -->
  <joint name="joint4" type="revolute">
    <parent link="link4"/>
    <child link="link5"/>
    <origin rpy="0 0 0" xyz="0.0 -0.187 0.0"/>
    <axis xyz="0 0 1"/>
    <limit effort="1000" lower="-2.8274333886" upper="2.8274333886" velocity="6.5"/>
  </joint>
  <!-- Transmission 4 -->
  <transmission name="tran4">
    <type>transmission_interface/SimpleTransmission</type>
    <joint name="joint4">
      <hardwareInterface>PositionJointInterface</hardwareInterface>
    </joint>
    <actuator name="motor4">
      <hardwareInterface>PositionJointInterface</hardwareInterface>
      <mechanicalReduction>1</mechanicalReduction>
    </actuator>
  </transmission>
  <!--  Link 5 -->
  <link name="link5">
    <collision>
      <origin rpy="0 0 0" xyz="0.0 0.205 0.053"/>
      <geometry>
        <mesh filename="package://romo_ros/meshes/left_chain_link5.stl"/>
      </geometry>
    </collision>
    <visual>
      <origin rpy="0 0 0" xyz="0.0 0.205 0.053"/>
      <geometry>
        <mesh filename="package://romo_ros/meshes/left_chain_link5.stl"/>
      </geometry>
      <material name="grey"/>
    </visual>
    <inertial>
      <origin xyz="0 0.205 0.053"/>
      <mass value="0.4"/>
      <inertia ixx="0.001" ixy="0.0" ixz="0.0" iyy="0.001" iyz="0.0" izz="0.001"/>
    </inertial>
  </link>
  <!--  Joint 5 -->
  <joint name="joint5" type="revolute">
    <parent link="link5"/>
    <child link="link6"/>
    <origin rpy="0 0 0" xyz="0.036 0.0 0.0"/>
    <axis xyz="1 0 0"/>
    <limit effort="1000" lower="-2.8274333886" upper="2.8274333886" velocity="6.5"/>
  </joint>
  <!-- Transmission 5 -->
  <transmission name="tran5">
    <type>transmission_interface/SimpleTransmission</type>
    <joint name="joint5">
      <hardwareInterface>PositionJointInterface</hardwareInterface>
    </joint>
    <actuator name="motor5">
      <hardwareInterface>PositionJointInterface</hardwareInterface>
      <mechanicalReduction>1</mechanicalReduction>
    </actuator>
  </transmission>
  <!--  Link 6 -->
  <link name="link6">
    <collision>
      <origin rpy="0 0 0" xyz="-0.036 0.205 0.053"/>
      <geometry>
        <mesh filename="package://romo_ros/meshes/left_chain_link6.stl"/>
      </geometry>
    </collision>
    <visual>
      <origin rpy="0 0 0" xyz="-0.036 0.205 0.053"/>
      <geometry>
        <mesh filename="package://romo_ros/meshes/left_chain_link6.stl"/>
      </geometry>
      <material name="grey"/>
    </visual>
    <inertial>
      <origin xyz="-0.036 0.205 0.053"/>
      <mass value="0.4"/>
      <inertia ixx="0.001" ixy="0.0" ixz="0.0" iyy="0.001" iyz="0.0" izz="0.001"/>
    </inertial>
  </link>
  <!--  Joint 6 -->
  <joint name="joint6" type="revolute">
    <parent link="link6"/>
    <child link="link7"/>
    <origin rpy="0 0 0" xyz="0.22 0.0 0.0"/>
    <axis xyz="0 1 0"/>
    <limit effort="1000" lower="-2.8274333886" upper="2.8274333886" velocity="6.5"/>
  </joint>
  <!-- Transmission 6 -->
  <transmission name="tran6">
    <type>transmission_interface/SimpleTransmission</type>
    <joint name="joint6">
      <hardwareInterface>PositionJointInterface</hardwareInterface>
    </joint>
    <actuator name="motor6">
      <hardwareInterface>PositionJointInterface</hardwareInterface>
      <mechanicalReduction>1</mechanicalReduction>
    </actuator>
  </transmission>
  <!--  Link 7 -->
  <link name="link7">
    <collision>
      <origin rpy="0 0 0" xyz="-0.256 0.205 0.053"/>
      <geometry>
        <mesh filename="package://romo_ros/meshes/left_chain_gripper_fix.stl"/>
      </geometry>
    </collision>
    <visual>
      <origin rpy="0 0 0" xyz="-0.256 0.205 0.053"/>
      <geometry>
        <mesh filename="package://romo_ros/meshes/left_chain_gripper_fix.stl"/>
      </geometry>
      <material name="grey"/>
    </visual>
    <inertial>
      <origin xyz="-0.256 0.205 0.053"/>
      <mass value="0.4"/>
      <inertia ixx="0.001" ixy="0.0" ixz="0.0" iyy="0.001" iyz="0.0" izz="0.001"/>
    </inertial>
  </link>
  <!--  grip_joint -->
  <joint name="grip_joint" type="revolute">
    <parent link="link7"/>
    <child link="grip_link"/>
    <origin rpy="0 0 0" xyz="0.06 0.0 -0.015"/>
    <axis xyz="0 1 0"/>
    <limit effort="1000" lower="-2.8274333886" upper="2.8274333886" velocity="6.5"/>
  </joint>
  <!--  Grip link -->
  <link name="grip_link">
    <collision>
      <origin rpy="0 0 0" xyz="-0.316 0.205 0.068"/>
      <geometry>
        <mesh filename="package://romo_ros/meshes/left_chain_gripper_move.stl"/>
      </geometry>
    </collision>
    <visual>
      <origin rpy="0 0 0" xyz="-0.316 0.205 0.068"/>
      <geometry>
        <mesh filename="package://romo_ros/meshes/left_chain_gripper_move.stl"/>
      </geometry>
      <material name="grey"/>
    </visual>
    <inertial>
      <origin xyz="-0.316 0.205 0.068"/>
      <mass value="0.2"/>
      <inertia ixx="0.001" ixy="0.0" ixz="0.0" iyy="0.001" iyz="0.0" izz="0.001"/>
    </inertial>
  </link>
  <!--  Grip joint -->
  <!--<joint name="grip_joint" type="revolute">
    <parent link="link7"/>
    <child link="grip_link"/>
    <origin xyz="0.0 0.0 0.0" rpy="0 0 0"/>
    <axis xyz="1 0 0"/>
    <limit velocity="6.5" effort="1000" lower="${-pi*0.9}" upper="${pi*0.9}" />
  </joint>-->
  <!-- Transmission 5 -->
  <!--<transmission name="tran5">
    <type>transmission_interface/SimpleTransmission</type>
    <joint name="grip_joint">
      <hardwareInterface>PositionJointInterface</hardwareInterface>
    </joint>
    <actuator name="motor7">
      <hardwareInterface>PositionJointInterface</hardwareInterface>
      <mechanicalReduction>1</mechanicalReduction>
    </actuator>
  </transmission>-->
  <!--  Grip link sub -->
  <!--<link name="grip_link_sub">
    <collision>
      <origin xyz="0 -0.047 0" rpy="0 0 0"/>
      <geometry>
        <mesh filename="package://romo_ros/meshes/left_chain_link_grip_r.stl" scale="0.001 0.001 0.001"/>
      </geometry>
    </collision>

    <visual>
      <origin xyz="0 -0.047 0" rpy="0 0 0"/>
      <geometry>
        <mesh filename="package://romo_ros/meshes/left_chain_link_grip_r.stl" scale="0.001 0.001 0.001"/>
      </geometry>
      <material name="grey"/>
    </visual>

    <inertial>
      <origin xyz="0 0 0" />
      <mass value="0.01" />
      <inertia ixx="0.001" ixy="0.0" ixz="0.0"
               iyy="0.001" iyz="0.0"
               izz="0.001" />
    </inertial>
  </link>
  -->
  <!--  Grip joint sub -->
  <!--<joint name="grip_joint_sub" type="prismatic">
    <parent link="link5"/>
    <child link="grip_link_sub"/>
    <origin xyz="0.071 0.0 0" rpy="0 0 0"/>
    <axis xyz="0 1 0"/>
    <limit velocity="6.5" effort="1000" lower="-0.01" upper="0.035" />
  </joint>
  -->
  <!-- Transmission 6 -->
  <!--<transmission name="tran6">
    <type>transmission_interface/SimpleTransmission</type>
    <joint name="grip_joint_sub">
      <hardwareInterface>PositionJointInterface</hardwareInterface>
    </joint>
    <actuator name="motor8">
      <hardwareInterface>PositionJointInterface</hardwareInterface>
      <mechanicalReduction>1</mechanicalReduction>
    </actuator>
  </transmission>
  -->
</robot>

